Workbook
Name Aux_fatork: 'CEE CED'!#REF!
Name Aux_fatork: 'CEE CED'!#REF!
Name Aux_FC: 'CEE CED'!#REF!
Name Aux_FC: 'CEE CED'!#REF!
Name CheckBoxIlum: "Check Box 68"
Name Lista_Atividade: Apoio!$AH$4:$AH$6
Name Lista_Confiabilidade: Apoio!#REF!
Name Lista_Confiabilidade: Apoio!#REF!
Name Lista_Empresa: Apoio!$AK$4:$AK$7
Name Lista_Localizacao: Apoio!$C$4:$C$400
Name Lista_Precisao: Apoio!#REF!
Name Lista_Precisao: Apoio!#REF!
Name Lista_SAS: Apoio!$AS$4:$AS$6
Name Lista_Solar: Apoio!$BS$4:$BS$29
Name Lista_SubgrupoTarifa: 'CEE CED'!$C$5:$C$15
Name Lista_Tarifa: Apoio!$AQ$4:$AQ$8
Name Lista_Tipologia: Apoio!$G$4:$G$9
Name Selecione_a_tipologia: Projeto!$J$10

Sheet Ajuda
C3: ÍNDICE | AD3: Voltar ao topo
D4: 1. | E4: Orientações gerais sobre a planilha
D5: 2. | E5: Guia do preenchimento das UCs (Unidades Consumidoras)
D6: 3. | E6: Guia do Cálculo dos custos do projeto
D7: 4. | E7: Guia do Cálculo dos benefícios do projeto
D8: 5. | E8: Ações de medição e verificação do projeto
D9: 6. | E9: Cronograma físico e financeiro
D10: 7. | E10: Projeção de economia de energia
D11: 8. | E11: Simulação das parcelas do contrato de desempenho
D12: 9. | E12: Disposições gerais
C16: ORIENTAÇÕES GERAIS SOBRE A PLANILHA | AD16: Voltar ao topo
D17: 1. | E17: Esta planilha deverá ser utilizada em conjunto com o Roteiro do Diagnóstico Energético, o Regulamento/Especificação Técnica
E18: da CPP e as Tabelas Auxiliares CEMIG.
D19: 2. | E19: A planilha realiza cálculos para uma única subclasse tarifária (nível de tensão de atendimento).
D20: 3. | E20: As seguintes avaliações devem ser realizadas nos projetos de eficiência energética, dependendo do estágio do projeto.
D21: 4. | E21: Avaliação ex ante: | J21: 4.1. | K21: Avaliação realizada através de valores estimados, na fase de definição do projeto.
J22: 4.2. | K22: Custos e benefícios são avaliados através de levantamentos, dados de catálogos e estimativas.
J23: 4.3. | K23: É a avaliação inicial do projeto, realizada antes do início do projeto.
J24: 4.4. | K24: Avaliação realizada para avaliar a viabilidade dos investimentos a serem realizados.
J25: 4.5. | K25: A avaliação ex ante apresentada nesta planilha é baseada no disposto no PROPEE.
D26: 5. | E26: Avaliação ex post: | J26: 5.1. | K26: Avaliação realizada através de valores consolidados, na fase de fechamento do projeto.
J27: 5.2. | K27: Custos e benefícios são avaliados em função dos custos despendidos e medições realizadas.
J28: 5.3. | K28: É a avaliação final do projeto, realizada após seu encerramento.
J29: 5.4. | K29: Avaliação realizada para apurar a viabilidade dos investimentos realizados.
J30: 5.5. | K30: A avaliação ex post será feita através da planilha disponibilizada pela Agência Nacional de Energia
K31: Elétrica - ANEEL e planilhas disponibilizadas pela Cemig.
D32: 6. | E32: A planilha realiza somente a avaliação ex ante do projeto.
D33: 7. | E33: A planilha realiza a avaliação dos custos do projeto nas duas situações descritas pelo Propee:
E34: 7.1. | F34: Ponto de vista do PEE: avaliam-se somente os custos despendidos pelo PEE.
E35: 7.2. | F35: Ponto de vista do projeto: avaliam-se todos os custos despendidos no projeto, independente da origem do recurso.
D36: 8. | E36: A planilha realiza a avaliação dos benefícios do projeto em uma situação descrita pelo PROPEE:
E37: 8.1 | F37: Ótica do sistema elétrico: valorando os benefícios em comparação pelo custo marginal de expansão do sistema.
E38: 8.2 | F38: Ótica do do consumidor: valorando os benefícios pelo custo efetivamente pago pelo consumidor (Fonte Incentivada).
D39: 9. | E39: A planilha apresenta uma estimativa das parcelas do contrato de desempenho, não refletindo necessariamente a
E40: situação final, uma vez que podem haver diferenças entre as metas previstas e realizadas de custos e benefícios, bem
E41: como pode haver a variação da taxa de referência utilizada na simulação (IPCA).
D42: 10. | E42: A planilha realiza uma projeção da economia de energia a ser obtida com a realização do projeto de eficiência energética.
E43: A utilização desta planilha é obrigatória. O principal objetivo desta projeção é proporcionar uma ferramenta para a verificação
E44: da coerência dos dados utilizados nos cálculos.
D45: 11. | E45: O preenchimento de toda planilha deve ser feito apenas nas células em branco. Todas as outras células de cor azul
...

Sheet Fluxo
G2: *** As células possuem links para as respectivas guias do arquivo.
S17: Legenda:
U19: Planilha RCB (preenchimento obrigatório)
U21: Planilha "Tabelas Auxiliares CEMIG" (preenchimento obrigatório)

Sheet CEE CED
B2: CEE E CED
B3: Valores de CEE e CED para utilização em projetos de eficiência energética
B4: Subclasse tarifária | D4: CEE | E4: CED | F4: FC | G4: k
B5: 1 | C5: Selecione a subclasse tarifária | D5: 0 | E5: 0 | F5: 0 | G5: 0
B6: 2 | C6: A1 - Acima de 230 kV | F6: 0.7 | G6: 0.15
B7: 3 | C7: A2 - De 88 kV a 230 kV | D7: 429.6 | E7: 341.73 | F7: 0.7 | G7: 0.15
B8: 4 | C8: A3 - 69 kV | D8: 452.36 | E8: 526.86 | F8: 0.7 | G8: 0.15
B9: 5 | C9: A3a - De 30 kV a 44 kV | D9: 506.48 | E9: 1009.76 | F9: 0.7 | G9: 0.15
B10: 6 | C10: A4 - De 2,3 kV a 25 kV | D10: 506.48 | E10: 1009.76 | F10: 0.7 | G10: 0.15
B11: 7 | C11: AS - Subterrâneo | D11: 574.31 | E11: 1472.68 | F11: 0.7 | G11: 0.15
B12: 8 | C12: B1 - Baixa tensão (residencial) | D12: 320.97 | E12: 2062.63 | F12: 0.7 | G12: 0.15
B13: 9 | C13: B2 - Baixa tensão (rural) | D13: 320.97 | E13: 2180.34 | F13: 0.7 | G13: 0.15
B14: 12 | C14: B3 - Baixa tensão (demais classes) | D14: 320.97 | E14: 2121.48 | F14: 0.7 | G14: 0.15
B15: 13 | C15: B4 - Iluminação Pública | D15: 320.97 | E15: 2121.48 | F15: 0.7 | G15: 0.15
B17: =SUMIF(Lista_SubgrupoTarifa,C17,B5:B14) -> 1 | C17: =Projeto!J24 -> Selecione a subclasse tarifária | D17: =IF(C17="A1 - Acima de 230 kV","Não Permitido",SUMIF($C$5:$C$15,$C$17,$D$5:$D$15)) -> 0 | E17: =IF(C17="A1 - Acima de 230 kV","Não Permitido",SUMIF($C$5:$C$15,$C$17,$E$5:$E$15)) -> 0 | F17: =SUMIF($C$5:$C$15,$C$17,$F$5:$F$15) -> 0 | G17: =SUMIF($C$5:$C$15,$C$17,$G$5:$G$15) -> 0
D19: Número | E19: Data
C20: Resolução Homologatória ANEEL | D20: 3589 | E20: 46168

Sheet Avaliação
C3: CRITÉRIOS PARA AVALIAÇÃO DA CHAMADA PÚBLICA
C4: Nesta planilha estão dispostos os critérios para pontuação dos projetos apresentados na chamada pública. Os demais
C5: critérios são dependentes da documentação apresentada pelo proponente, dos demais projetos apresentados ou da
C6: avaliação da comissão julgadora.
C10: ITEM | D10: CRITÉRIO | F10: VALOR
C11: A | D11: Relação custo-benefício
D12: RCB | E12: Relação custo-benefício do projeto | F12: =RCB!H9 -> 0
C14: B | D14: Peso do investimento em equipamentos no custo total
D15: K | E15: Custo do equipamento comparticipado pelo PEE | F15: =CustoContábil!F6 -> 0
D16: CT | E16: Custo total do investimento considerando os custos aportados pelo PEE | F16: =CustoContábil!F18 -> 0
C18: C | D18: Impacto direto na economia de energia e na redução de demanda
D19: EP | E19: Energia economizada pelo projeto (MWh/ano) | F19: =RCB!C18 -> 1.296
D20: DP | E20: Demanda evitada pelo projeto (kW) | F20: =RCB!D18 -> 0
C22: D | D22: Qualidade na apresentação do projeto
D23: n/a | E23: Prova documental / comissão julgadora
C25: E | D25: Capacidade de superar barreiras de mercado e efeito multiplicador
D26: n/a | E26: Prova documental / comissão julgadora
C28: F | D28: Experiência em projetos semelhantes
D29: n/a | E29: Prova documental / comissão julgadora
C31: G | D31: Contrapartida
D32: INVPEE | E32: Investimento aportado pelo PEE | F32: =CustoContábil!F18 -> 0
D33: INVtotal | E33: Investimento total do projeto | F33: =CustoContábil!D18 -> 0
C35: H | D35: Incentico à usos finais
D36: UF1 | E36: Investimento do PEE considerado para o uso final 1 (iluminação) | F36: =IlumCusto!K165 -> 0
D37: UF2 | E37: Investimento do PEE considerado para o uso final 2 (condicionamento ambiental) | F37: =CondAmbCusto!K115 -> 0
D38: UF3 | E38: Investimento do PEE considerado para o uso final 3 (sistemas motrizes) | F38: =MotorCusto!K115 -> 0
D39: UF4 | E39: Investimento do PEE considerado para o uso final 4 (sistemas de refrigeração) | F39: =RefrigCusto!K115 -> 0
D40: UF6 | E40: Investimento do PEE considerado para o uso final 6 (equipamentos hospitalares) | F40: =HospCusto!K115 -> 0
D41: UF7 | E41: Investimento do PEE considerado para o uso final 7 (usina fotovoltaica) | F41: =UFVCusto!K115 -> 0
D42: UF8 | E42: Investimento do PEE considerado para o uso final 8 (outros) | F42: =OutrosCusto!K115 -> 0
C44: I | D44: Ações educacionais, divulgação e gestão
D45: INVaed | E45: Investimento aplicado em treinamentos | F45: =CustoContábil!D14 -> 0
D46: INVge | E46: Investimento aplicado em gestão energética | F46: 0
D47: INVtotal | E47: Investimento total do projeto | F47: =CustoContábil!D18 -> 0

Sheet Apoio
B2: INFORMAÇÕES SOBRE O PROJETO - Planilha_RCB_CPP2026_REV01 | AA2: INFORMAÇÕES SOBRE AS FATURAS DE ENERGIA ELÉTRICA DAS UCs | AG2: INFORMAÇÕES SOBRE A UNIDADE CONSUMIDORA | AU2: ESTIMATIVA DE CUSTOS DA CONCESSIONÁRIA APLICADOS NO PROJETO | BJ2: CONTRATO DE DESEMPENHO | BS2: AQUECIMENTO SOLAR DE ÁGUA
B3: Localização | D3: Distância | F3: Tipologia | I3: Tipo desta Planilha RCB | L3: Usos finais previstos - Ex ante | O3: Chamada pública | R3: RCB limite | U3: RCB limite CP | X3: Mensagem avaliação RCB | AA3: Ambiente de contratação de energia | AD3: Número de fases do padrão de entrada | AG3: Forma de contratação | AJ3: Atividade | AM3: Retorno do investimento | AP3: Tarifa | AU3: Divisão de valores | AX3: Mão de obra própria CEMIG | BA3: Transporte CEMIG | BD3: Administração própria CEMIG | BG3: Auditoria Contábil e Financeira CEMIG | BJ3: Taxas | BM3: Divisão da vida útil ex ante | BQ3: Vida útil (anos) | BS3: Cidade | BT3: Fator de correção
B4: 1 | C4: Selecione o município | D4: 0 | F4: 1 | G4: Selecione a tipologia | I4: 1 | J4: Selecione o tipo desta Planilha RCB | L4: Iluminação | M4: =IF(AND(RCB!E9=0,RCB!F9=0),"não",IF(OR(RCB!E9>0,RCB!F9>0),"sim","erro")) -> não | O4: Marcar para chamada pública | P4: X | R4: 1 | S4: 0.8 | U4: 1 | V4: 0.75 | X4: 1 | Y4: Avaliação preliminar do projeto conforme critérios ANEEL | AA4: 1 | AB4: Selecione o tipo de contratação | AD4: 1 | AE4: Selecione a quantidade de fases | AG4: 1 | AH4: Selecione a forma de Contratação | AJ4: 1 | AK4: Selecione o tipo de empresa | AM4: Não selecionado | AN4: 0 | AP4: 1 | AQ4: Selecione a modalidade tarifária | AS4: Não selecionado | AU4: Iluminação | AV4: =IF(CustoContábil!$F$6=0,0,IlumCusto!K108/CustoContábil!$F$6) -> 0 | AX4: Iluminação | AY4: =IF($AV$13=0,0,$AY$13*AV4) -> 0 | BA4: Iluminação | BB4: =IF($AV$13=0,0,$BB$13*AV4) -> 0 | BD4: Iluminação | BE4: =IF($AV$13=0,0,$BE$13*AV4) -> 0 | BG4: Iluminação | BH4: =IF($AV$13=0,0,$BH$15*AV4) -> 0 | BJ4: IPCA mensal de referência | BK4: 0.0016 | BM4: Iluminação | BN4: =RCB!C9 -> 0 | BO4: MWh/ano | BQ4: =IF(COUNT(IlumCusto!V8:V107)=0,0,AVERAGE(IlumCusto!V8:V107)) -> 0 | BS4: Aracaju - SE | BT4: 0.84
B5: 2 | C5: ABADIA DOS DOURADOS | D5: 547 | F5: 2 | G5: Industrial | I5: 2 | J5: Geral Viáveis | L5: Condicionamento ambiental | M5: =IF(AND(RCB!E10=0,RCB!F10=0),"não",IF(OR(RCB!E10>0,RCB!F10>0),"sim","erro")) -> não | R5: 2 | S5: 0.9 | U5: 2 | V5: 0.85 | AA5: 2 | AB5: Cliente Cativo | AD5: 2 | AE5: Monofásico (1 fase) | AG5: 2 | AH5: Contrato de Desempenho | AJ5: 2 | AK5: Micro ou pequena empresa | AM5: Micro ou pequena empresa | AN5: 0.8 | AP5: 2 | AQ5: Tarifa convencional | AS5: Convencional | AU5: Condicionamento ambiental | AV5: =IF(CustoContábil!$F$6=0,0,CondAmbCusto!K58/CustoContábil!F6) -> 0 | AX5: Condicionamento ambiental | AY5: =IF($AV$13=0,0,$AY$13*AV5) -> 0 | BA5: Condicionamento ambiental | BB5: =IF($AV$13=0,0,$BB$13*AV5) -> 0 | BD5: Condicionamento ambiental | BE5: =IF($AV$13=0,0,$BE$13*AV5) -> 0 | BG5: Condicionamento ambiental | BH5: =IF($AV$13=0,0,$BH$15*AV5) -> 0 | BJ5: Mês referência IPCA | BK5: 46174 | BM5: Condicionamento ambiental | BN5: =RCB!C10 -> 0 | BO5: MWh/ano | BQ5: =IF(COUNT(CondAmbCusto!V8:V57)=0,0,AVERAGE(CondAmbCusto!V8:V57)) -> 0 | BS5: Belém - PA | BT5: 0.65
B6: 3 | C6: ABAETÉ | D6: 213 | F6: 3 | G6: Comércio e serviços | I6: 3 | J6: Geral Inviáveis | L6: Sistemas motrizes | M6: =IF(AND(RCB!E11=0,RCB!F11=0),"não",IF(OR(RCB!E11>0,RCB!F11>0),"sim","erro")) -> não | O6: =IF(P4="","Projeto fora da chamada pública","Projeto de chamada pública") -> Projeto de chamada pública | R6: 3 | S6: 0.8 | U6: 3 | V6: 0.75 | X6: 2 | Y6: Avaliação preliminar do projeto conforme chamada pública | AA6: 3 | AB6: Cliente Livre | AD6: 3 | AE6: Bifásico (2 fases) | AG6: 3 | AH6: Fundo Perdido | AJ6: 3 | AK6: Demais empresas | AM6: Demais empresas | AN6: 1 | AP6: 3 | AQ6: Tarifa verde | AS6: Central de água quente | AU6: Motores | AV6: =IF(CustoContábil!$F$6=0,0,MotorCusto!K58/CustoContábil!F6) -> 0 | AX6: Motores | AY6: =IF($AV$13=0,0,$AY$13*AV6) -> 0 | BA6: Motores | BB6: =IF($AV$13=0,0,$BB$13*AV6) -> 0 | BD6: Motores | BE6: =IF($AV$13=0,0,$BE$13*AV6) -> 0 | BG6: Motores | BH6: =IF($AV$13=0,0,$BH$15*AV6) -> 0 | BJ6: Multa atraso | BK6: 0.02 | BM6: Motores | BN6: =RCB!C11 -> 0 | BO6: MWh/ano | BQ6: =IF(COUNT(MotorCusto!V8:V57)=0,0,AVERAGE(MotorCusto!V8:V57)) -> 0 | BS6: Belo Horizonte - MG | BT6: 0.68
B7: 4 | C7: ABRE CAMPO | D7: 216 | F7: 4 | G7: Poder Público | L7: Sistemas de refrigeração | M7: =IF(AND(RCB!E12=0,RCB!F12=0),"não",IF(OR(RCB!E12>0,RCB!F12>0),"sim","erro")) -> não | AD7: 4 | AE7: Trifásico (3 fases) | AJ7: 4 | AK7: Não se aplica (fundo perdido) | AM7: Não se aplica | AN7: 1 | AP7: 4 | AQ7: Tarifa azul | AU7: Sistemas de refrigeração | AV7: =IF(CustoContábil!$F$6=0,0,RefrigCusto!K58/CustoContábil!F6) -> 0 | AX7: Sistemas de refrigeração | AY7: =IF($AV$13=0,0,$AY$13*AV7) -> 0 | BA7: Sistemas de refrigeração | BB7: =IF($AV$13=0,0,$BB$13*AV7) -> 0 | BD7: Sistemas de refrigeração | BE7: =IF($AV$13=0,0,$BE$13*AV7) -> 0 | BG7: Sistemas de refrigeração | BH7: =IF($AV$13=0,0,$BH$15*AV7) -> 0 | BM7: Sistemas de refrigeração | BN7: =RCB!C12 -> 0 | BO7: MWh/ano | BQ7: =IF(COUNT(RefrigCusto!V8:V57)=0,0,AVERAGE(RefrigCusto!V8:V57)) -> 0 | BS7: Brasília - DF | BT7: 0.7
B8: 5 | C8: ACAIACA | D8: 158 | F8: 5 | G8: Rural | L8: Equipamentos hospitalares | M8: =IF(AND(RCB!E13=0,RCB!F13=0),"não",IF(OR(RCB!E13>0,RCB!F13>0),"sim","erro")) -> não | R8: =$AG$8 -> 1 | S8: =IF(AND(($AV$9+$AV$10+$AV$12>0),(SUM($AV$4:$AV$8,$AV$11)=0)),0.9,IF($P$4="",SUMIF($R$4:$R$6,$R$8,$S$4:$S$6),SUMIF($U$4:$U$6,$R$8,$V$4:$V$6))) -> 0.75 | AG8: =SUMIF(Lista_Atividade,AH8,AG4:AG6) -> 1 | AH8: =Projeto!J21 -> Selecione a forma de Contratação | AP8: 5 | AQ8: Tarifa branca | AS8: Selecione o Tipo do Sistema | AU8: Equipamentos hospitalares | AV8: =IF(CustoContábil!$F$6=0,0,HospCusto!K58/CustoContábil!F6) -> 0 | AX8: Equipamentos hospitalares | AY8: =IF($AV$13=0,0,$AY$13*AV8) -> 0 | BA8: Equipamentos hospitalares | BB8: =IF($AV$13=0,0,$BB$13*AV8) -> 0 | BD8: Equipamentos hospitalares | BE8: =IF($AV$13=0,0,$BE$13*AV8) -> 0 | BG8: Equipamentos hospitalares | BH8: =IF($AV$13=0,0,$BH$15*AV8) -> 0 | BM8: Equipamentos hospitalares | BN8: =RCB!C13 -> 0 | BO8: MWh/ano | BQ8: =IF(COUNT(HospCusto!V8:V57)=0,0,AVERAGE(HospCusto!V8:V57)) -> 0 | BS8: Campo Grande - MS | BT8: 0.73
B9: 6 | C9: AÇUCENA | D9: 280 | F9: 6 | G9: Residencial (Condomínios) | L9: Fotovoltaico | M9: =IF(AND(RCB!E14=0,RCB!F14=0),"não",IF(OR(RCB!E14>0,RCB!F14>0),"sim","erro")) -> não | X9: =IF(P4="",X4,X6) -> 2 | Y9: =IF(P4="",Y4,Y6) -> Avaliação preliminar do projeto conforme chamada pública | AJ9: =SUMIF(Lista_Empresa,AK9,AJ4:AJ7) -> 1 | AK9: =Projeto!J22 -> Selecione o tipo de empresa | AM9: Retorno do investimento | AN9: =IF(AJ9=2,AN5,IF(AJ9=3,AN6,IF(AJ9=4,AN7,AN4))) -> 0 | AU9: Usina Fotovoltaica | AV9: =IF(CustoContábil!$F$6=0,0,UFVCusto!K58/CustoContábil!F6) -> 0 | AX9: Usina Fotovoltaica | AY9: =IF($AV$13=0,0,$AY$13*AV9) -> 0 | BA9: Usina Fotovoltaica | BB9: =IF($AV$13=0,0,$BB$13*AV9) -> 0 | BD9: Usina Fotovoltaica | BE9: =IF($AV$13=0,0,$BE$13*AV9) -> 0 | BG9: Usina Fotovoltaica | BH9: =IF($AV$13=0,0,$BH$15*AV9) -> 0 | BM9: Usina Fotovoltaica | BN9: =RCB!C14 -> 1.296 | BO9: MWh/ano | BQ9: =IF(COUNT(UFVCusto!V8:V57)=0,0,AVERAGE(UFVCusto!V8:V57)) -> 0 | BS9: Cuiabá - MT | BT9: 0.74
B10: 7 | C10: ÁGUA BOA | D10: 379 | F10: 7 | G10: Serviço público | L10: Outras Fontes Incentivadas | M10: =IF(AND(RCB!E15=0,RCB!F15=0),"não",IF(OR(RCB!E15>0,RCB!F15>0),"sim","erro")) -> não | AP10: =SUMIF(Lista_Tarifa,AQ10,AP4:AP8) -> 1 | AQ10: =Projeto!J23 -> Selecione a modalidade tarifária | AU10: Outras Fontes Incentivadas | AV10: =IF(CustoContábil!$F$6=0,0,OutrasFICusto!K58/CustoContábil!F6) -> 0 | AX10: Outras Fontes Incentivadas | AY10: =IF($AV$13=0,0,$AY$13*AV10) -> 0 | BA10: Outras Fontes Incentivadas | BB10: =IF($AV$13=0,0,$BB$13*AV10) -> 0 | BD10: Outras Fontes Incentivadas | BE10: =IF($AV$13=0,0,$BE$13*AV10) -> 0 | BG10: Outras Fontes Incentivadas | BH10: =IF($AV$13=0,0,$BH$15*AV10) -> 0 | BM10: Outras Fontes Incentivadas | BN10: =RCB!C15 -> 0 | BO10: MWh/ano | BQ10: =IF(COUNT(OutrasFICusto!V8:V57)=0,0,AVERAGE(OutrasFICusto!V8:V57)) -> 0 | BS10: Curitiba - PR | BT10: 0.49
B11: 8 | C11: ÁGUA COMPRIDA | D11: 513 | F11: 8 | G11: Iluminação Pública | L11: Outros | M11: =IF(AND(RCB!E16=0,RCB!F16=0),"não",IF(OR(RCB!E16>0,RCB!F16>0),"sim","erro")) -> não | AU11: Outros | AV11: =IF(CustoContábil!$F$6=0,0,OutrosCusto!K58/CustoContábil!F6) -> 0 | AX11: Outros | AY11: =IF($AV$13=0,0,$AY$13*AV11) -> 0 | BA11: Outros | BB11: =IF($AV$13=0,0,$BB$13*AV11) -> 0 | BD11: Outros | BE11: =IF($AV$13=0,0,$BE$13*AV11) -> 0 | BG11: Outros | BH11: =IF($AV$13=0,0,$BH$15*AV11) -> 0 | BM11: Outros | BN11: =RCB!C16 -> 0 | BO11: MWh/ano | BQ11: =IF(COUNT(OutrosCusto!V8:V57)=0,0,AVERAGE(OutrosCusto!V8:V57)) -> 0 | BS11: Florianópolis - SC | BT11: 0.55
B12: 9 | C12: AGUANIL | D12: 239 | L12: SAE | M12: =IF(AND(RCB!E17=0,RCB!F17=0),"não",IF(OR(RCB!E17>0,RCB!F17>0),"sim","erro")) -> não | AU12: SAE | AV12: =IF(CustoContábil!$F$6=0,0,SAECusto!K58/CustoContábil!F6) -> 0 | AX12: SAE | AY12: =IF($AV$13=0,0,$AY$13*AV12) -> 0 | BA12: SAE | BB12: =IF($AV$13=0,0,$BB$13*AV12) -> 0 | BD12: SAE | BE12: =IF($AV$13=0,0,$BE$13*AV12) -> 0 | BG12: SAE | BH12: =IF($AV$13=0,0,$BH$15*AV12) -> 0 | BM12: SAE | BN12: =RCB!C17 -> 0 | BO12: MWh/ano | BQ12: =IF(COUNT(SAECusto!V8:V57)=0,0,AVERAGE(SAECusto!V8:V57)) -> 0 | BS12: Fortaleza - CE | BT12: 0.82
B13: 10 | C13: ÁGUAS FORMOSAS | D13: 610 | AU13: TOTAL | AV13: =SUM(AV4:AV12) -> 0 | AX13: TOTAL | AY13: =(AY16*AY17)+(AY20*AY21) -> 29535.52 | BA13: TOTAL | BB13: =BB17*(96+(BB18*BB15)) -> 0 | BD13: TOTAL | BE13: =BE16*SUM(BE17,BE18, BE20, BE21, BE22) - BE19 -> 0 | BG13: TOTAL | BH13: =SUM(BH4:BH12) -> 0 | BM13: TOTAL | BN13: =SUM(BN4:BN12) -> 1.296 | BO13: MWh/ano | BQ13: =IF(BN13=0,0,(BQ5*(BN5/BN13))+(BQ6*(BN6/BN13))+(BQ7*(BN7/BN13))+(BQ8*(BN8/BN13))+(BQ9*(BN9/BN13))+(BQ10*(BN10/BN13))+(BQ12*(BN12/BN13))+(BQ11*(BN11/BN13))+BQ4*(BN4/BN13)) -> 0 | BS13: Goiânia - GO | BT13: 0.78
B14: 11 | C14: ÁGUAS VERMELHAS | D14: 756 | BS14: João Pessoa - PB | BT14: 0.76
B15: 12 | C15: AIMORÉS | D15: 489 | AX15: Parcela fixa | BA15: Distância entre a cidade e BH | BB15: =IF(BB16="Selecione o município",0, LOOKUP(BB16,C6:C779,D6:D779)) -> 31 | BD15: Parcela variável | BG15: Custo Fixo | BH15: 1500 | BS15: Macapá - AP | BT15: 0.7
B16: 13 | C16: AIURUOCA | D16: 370 | AX16: Horas utilizadas | AY16: 154 | BA16: Cidade | BB16: =Projeto!J21 -> Selecione a forma de Contratação | BD16: Porcentagem | BE16: =1/19 -> 0.052631579 | BS16: Maceió - AL | BT16: 0.8
B17: 14 | C17: ALAGOA | D17: 400 | AX17: Custo homem-hora | AY17: 191.78909 | BA17: Tempo do Projeto (meses) | BB17: 0 | BD17: Materiais e Equipamentos | BE17: =CustoContábil!F6 -> 0 | BS17: Manaus - AM | BT17: 0.55
B18: 15 | C18: ALBERTINA | D18: 475 | BA18: Custo do km (CEMIG) | BB18: 0 | BD18: Mão de obra de terceiros | BE18: =CustoContábil!F8 -> 0 | BS18: Natal - RN | BT18: 0.81
B19: 16 | C19: ALFENAS | D19: 378 | AX19: Parcela variável | BD19: Marketing | BE19: =CustoContábil!F13 -> 0 | BS19: Porto Alegre - RS | BT19: 0.57
B20: 17 | C20: ALFREDO VASCONCELOS | D20: 161 | AX20: Porcentagem | AY20: 0.05 | BD20: Treinamento e capacitação | BE20: =CustoContábil!F14 -> 0 | BS20: Porto Nacional - TO | BT20: 0.74
B21: 18 | C21: ALMENARA | D21: 730 | AX21: Equip + MOT + MKT + Trein + | AY21: =SUM(BE17:BE22) -> 0 | BD21: Descarte de materiais | BE21: =CustoContábil!F15 -> 0 | BS21: Porto Velho - RO | BT21: 0.6
B22: 19 | C22: ALPERCATA | D22: 330 | AX22: Desc + M&V | BD22: Medição e verificação | BE22: =CustoContábil!F16 -> 0 | BS22: Recife - PE | BT22: 0.77
B23: 20 | C23: ALPINÓPOLIS | D23: 332 | BS23: Ribeirão Preto - SP | BT23: 0.69
B24: 21 | C24: ALTEROSA | D24: 394 | BS24: Rio de Janeiro - RJ | BT24: 0.6
B25: 22 | C25: ALTO CAPARAÓ | D25: 322 | BS25: Salvador - BA | BT25: 0.7
B26: 23 | C26: ALTO RIO DOCE | D26: 224 | BS26: São Luís - MA | BT26: 0.73
B27: 24 | C27: ALVARENGA | D27: 464 | BS27: São Paulo - SP | BT27: 0.5
B28: 25 | C28: ALVINÓPOLIS | D28: 163 | BS28: Teresina - PI | BT28: 0.86
B29: 26 | C29: ALVORADA DE MINAS | D29: 342 | BS29: Vitória - ES | BT29: 0.65
B30: 27 | C30: AMPARO DO SERRA | D30: 203 | BS30: Condições:
B31: 28 | C31: ANDRADAS | D31: 498 | BS31: Temperatura de armazenamento = 40°C
B32: 29 | C32: ANDRELÂNDIA | D32: 280 | BS32: Volume armazenado = Volume consumido
B33: 30 | C33: ANGELÂNDIA | D33: 449
B34: 31 | C34: ANTÔNIO CARLOS | D34: 190
B35: 32 | C35: ANTÔNIO DIAS | D35: 172
B36: 33 | C36: ARAÇAÍ | D36: 122
B37: 34 | C37: ARACITABA | D37: 225
B38: 35 | C38: ARAÇUAÍ | D38: 678
B39: 36 | C39: ARAGUARI | D39: 569
B40: 37 | C40: ARANTINA | D40: 304
B41: 38 | C41: ARAPORÃ | D41: 670
...

Sheet Projeto
R5: PROGRAMA DE EFICIÊNCIA ENERGÉTICA - CHAMADA PÚBLICA DE PROJETOS
C7: IDENTIFICAÇÃO DO PROJETO
D8: Concessionária | J8: Cemig Distribuição S.A. | AA8: CNPJ | AB8: 6981180000116
D9: Nome do projeto
D10: Tipologia do projeto | J10: Selecione a tipologia | AC10: Taxa de desconto (i) | AD10: 0.08
D11: Tipo desta Planilha RCB | J11: Selecione o tipo desta Planilha RCB
C13: IDENTIFICAÇÃO DO CONSUMIDOR BENEFICIADO (UC Principal)
D14: Nome
D15: Endereço
D16: CNPJ
D17: Nº da Unidade Consumidora
D18: Responsável
D19: Telefone | Q19: e-mail
D20: Município
D21: Forma de Contratação | J21: Selecione a forma de Contratação
D22: Porte de empresa | J22: Selecione o tipo de empresa
D23: Modalidade tarifária | J23: Selecione a modalidade tarifária
D24: Subclasse tarifária | J24: Selecione a subclasse tarifária
C26: IDENTIFICAÇÃO DA EMPRESA RESPONSÁVEL PELO PROJETO
D27: Nome da empresa
D28: Endereço
D29: CNPJ
D30: Responsável técnico
D31: Telefone | P31: e-mail
C35: AVALIAÇÃO EX ANTE - RESUMO DAS AÇÕES PREVISTAS NO PROJETO
C37: Usos Finais contemplados: | J37: =_xlfn.TEXTJOIN( "; ", TRUE, IF(RCB!G9>0,IF(Projeto!J24="B4 - Iluminação Pública","Iluminação pública","Iluminação"),""), IF(RCB!G10>0,"Condicionamento ambiental",""), IF(RCB!G11>0,"Sistemas motrizes ("&MotorBenef!E2&")",""), IF(RCB!G12>0,"Sistemas de refrigeração ("&RefrigBenef!E2&")",""), IF(RCB!G13>0,"Equipamentos hospitalares ("&HospBenef!E2&")",""), IF(RCB!G14>0,IF(RCB!G17>0,"Usina Fotovoltaica + SAE","Usina Fotovoltaica"),""), IF(RCB!G15>0,"Outras Fontes incentivadas ("&OutrasFIBenef!E2&")",""), IF(RCB!G16>0,"Outros ("&OutrosBenef!E2&")","") ) | AJ37: =IF(AND(RCB!G17>0,RCB!G14<=0), "ERRO: SAE exige Usina Fotovoltaica", "")
C42: VALORES DE CEE E CED - EX ANTE
K43: CEE = | L43: ='CEE CED'!$D$17 -> 0 | Q43: R$/MWh | Z43: Fator de carga | AA43: ='CEE CED'!F17 -> 0
K44: CED = | L44: ='CEE CED'!$E$17 -> 0 | Q44: R$/kW ano | Z44: Constante k | AA44: ='CEE CED'!G17 -> 0
K46: Resolução homologatória ANEEL | L46: ='CEE CED'!D20 -> 3589 | Z46: Resolução publicada em | AA46: ='CEE CED'!E20 -> 46168
C48: CUSTO TOTAL DO PEE | L48: =CustoContábil!F18 -> 0 | T48: Valor total do projeto | AB48: =CustoContábil!D18 -> 0
C49: ENERGIA ECONOMIZADA | L49: =RCB!C18 -> 1.296 | Q49: MWh/ano | T49: Custo da energia economizada | AB49: =IF(RCB!C18=0,0,CustoContábil!F18/RCB!C18) -> 0 | AF49: R$/MWh
C50: REDUÇÃO DE DEMANDA NA PONTA | L50: =RCB!D18 -> 0 | Q50: kW | T50: Custo da demanda evitada | AB50: =IF(RCB!D18=0,0,CustoContábil!F18/RCB!D18) -> 0 | AF50: R$/kW
F52: RCBLIMITE = | L52: =Apoio!$S$8 -> 0.75 | U52: RCBEX ANTE = | AA52: =RCB!$H$9 -> 0
B55: =IF(CustoContábil!H21>CustoContábil!G21,"EXTRAPOLADO ALGUM LIMITE DE RECURSO POR RUBRICA, VER GUIA CustoContábil",IF(CustoContábil!H22>CustoContábil!G22,"EXTRAPOLADO ALGUM LIMITE DE RECURSO POR RUBRICA, VER GUIA CustoContábil",IF(CustoContábil!H23>CustoContábil!G23,"EXTRAPOLADO ALGUM LIMITE DE RECURSO POR RUBRICA, VER GUIA CustoContábil",IF(CustoContábil!H24>CustoContábil!G24,"EXTRAPOLADO ALGUM LIMITE DE RECURSO POR RUBRICA, VER GUIA CustoContábil",""))))

Sheet UCs
N2: 1 | O2: - Unidade consumidora: | U2: 2 | V2: - Unidade consumidora: | AB2: 3 | AC2: - Unidade consumidora: | AI2: 4 | AJ2: - Unidade consumidora: | AP2: 5 | AQ2: - Unidade consumidora: | AW2: 6 | AX2: - Unidade consumidora: | BD2: 7 | BE2: - Unidade consumidora: | BK2: 8 | BL2: - Unidade consumidora: | BR2: 9 | BS2: - Unidade consumidora: | BY2: 10 | BZ2: - Unidade consumidora: | CF2: 11 | CG2: - Unidade consumidora: | CM2: 12 | CN2: - Unidade consumidora: | CT2: 13 | CU2: - Unidade consumidora: | DA2: 14 | DB2: - Unidade consumidora: | DH2: 15 | DI2: - Unidade consumidora: | DO2: 16 | DP2: - Unidade consumidora: | DV2: 17 | DW2: - Unidade consumidora: | EC2: 18 | ED2: - Unidade consumidora: | EJ2: 19 | EK2: - Unidade consumidora: | EQ2: 20 | ER2: - Unidade consumidora:
N3: Identificação | U3: Identificação | AB3: Identificação | AI3: Identificação | AP3: Identificação | AW3: Identificação | BD3: Identificação | BK3: Identificação | BR3: Identificação | BY3: Identificação | CF3: Identificação | CM3: Identificação | CT3: Identificação | DA3: Identificação | DH3: Identificação | DO3: Identificação | DV3: Identificação | EC3: Identificação | EJ3: Identificação | EQ3: Identificação
N4: Nome ou razão social | U4: Nome ou razão social | AB4: Nome ou razão social | AI4: Nome ou razão social | AP4: Nome ou razão social | AW4: Nome ou razão social | BD4: Nome ou razão social | BK4: Nome ou razão social | BR4: Nome ou razão social | BY4: Nome ou razão social | CF4: Nome ou razão social | CM4: Nome ou razão social | CT4: Nome ou razão social | DA4: Nome ou razão social | DH4: Nome ou razão social | DO4: Nome ou razão social | DV4: Nome ou razão social | EC4: Nome ou razão social | EJ4: Nome ou razão social | EQ4: Nome ou razão social
N5: CNPJ | U5: CNPJ | AB5: CNPJ | AI5: CNPJ | AP5: CNPJ | AW5: CNPJ | BD5: CNPJ | BK5: CNPJ | BR5: CNPJ | BY5: CNPJ | CF5: CNPJ | CM5: CNPJ | CT5: CNPJ | DA5: CNPJ | DH5: CNPJ | DO5: CNPJ | DV5: CNPJ | EC5: CNPJ | EJ5: CNPJ | EQ5: CNPJ
N6: Endereço | U6: Endereço | AB6: Endereço | AI6: Endereço | AP6: Endereço | AW6: Endereço | BD6: Endereço | BK6: Endereço | BR6: Endereço | BY6: Endereço | CF6: Endereço | CM6: Endereço | CT6: Endereço | DA6: Endereço | DH6: Endereço | DO6: Endereço | DV6: Endereço | EC6: Endereço | EJ6: Endereço | EQ6: Endereço
N7: Cidade | U7: Cidade | AB7: Cidade | AI7: Cidade | AP7: Cidade | AW7: Cidade | BD7: Cidade | BK7: Cidade | BR7: Cidade | BY7: Cidade | CF7: Cidade | CM7: Cidade | CT7: Cidade | DA7: Cidade | DH7: Cidade | DO7: Cidade | DV7: Cidade | EC7: Cidade | EJ7: Cidade | EQ7: Cidade
N8: Estado | Q8: Minas Gerais | U8: Estado | X8: Minas Gerais | AB8: Estado | AE8: Minas Gerais | AI8: Estado | AL8: Minas Gerais | AP8: Estado | AS8: Minas Gerais | AW8: Estado | AZ8: Minas Gerais | BD8: Estado | BG8: Minas Gerais | BK8: Estado | BN8: Minas Gerais | BR8: Estado | BU8: Minas Gerais | BY8: Estado | CB8: Minas Gerais | CF8: Estado | CI8: Minas Gerais | CM8: Estado | CP8: Minas Gerais | CT8: Estado | CW8: Minas Gerais | DA8: Estado | DD8: Minas Gerais | DH8: Estado | DK8: Minas Gerais | DO8: Estado | DR8: Minas Gerais | DV8: Estado | DY8: Minas Gerais | EC8: Estado | EF8: Minas Gerais | EJ8: Estado | EM8: Minas Gerais | EQ8: Estado | ET8: Minas Gerais
N9: CEP | U9: CEP | AB9: CEP | AI9: CEP | AP9: CEP | AW9: CEP | BD9: CEP | BK9: CEP | BR9: CEP | BY9: CEP | CF9: CEP | CM9: CEP | CT9: CEP | DA9: CEP | DH9: CEP | DO9: CEP | DV9: CEP | EC9: CEP | EJ9: CEP | EQ9: CEP
N10: Horário de Funcionamento | P10: Início: | R10: Fim: | U10: Horário de Funcionamento | W10: Início: | Y10: Fim: | AB10: Horário de Funcionamento | AD10: Início: | AF10: Fim: | AI10: Horário de Funcionamento | AK10: Início: | AM10: Fim: | AP10: Horário de Funcionamento | AR10: Início: | AT10: Fim: | AW10: Horário de Funcionamento | AY10: Início: | BA10: Fim: | BD10: Horário de Funcionamento | BF10: Início: | BH10: Fim: | BK10: Horário de Funcionamento | BM10: Início: | BO10: Fim: | BR10: Horário de Funcionamento | BT10: Início: | BV10: Fim: | BY10: Horário de Funcionamento | CA10: Início: | CC10: Fim: | CF10: Horário de Funcionamento | CH10: Início: | CJ10: Fim: | CM10: Horário de Funcionamento | CO10: Início: | CQ10: Fim: | CT10: Horário de Funcionamento | CV10: Início: | CX10: Fim: | DA10: Horário de Funcionamento | DC10: Início: | DE10: Fim: | DH10: Horário de Funcionamento | DJ10: Início: | DL10: Fim: | DO10: Horário de Funcionamento | DQ10: Início: | DS10: Fim: | DV10: Horário de Funcionamento | DX10: Início: | DZ10: Fim: | EC10: Horário de Funcionamento | EE10: Início: | EG10: Fim: | EJ10: Horário de Funcionamento | EL10: Início: | EN10: Fim: | EQ10: Horário de Funcionamento | ES10: Início: | EU10: Fim:
N11: Dias de Funcionamento | U11: Dias de Funcionamento | AB11: Dias de Funcionamento | AI11: Dias de Funcionamento | AP11: Dias de Funcionamento | AW11: Dias de Funcionamento | BD11: Dias de Funcionamento | BK11: Dias de Funcionamento | BR11: Dias de Funcionamento | BY11: Dias de Funcionamento | CF11: Dias de Funcionamento | CM11: Dias de Funcionamento | CT11: Dias de Funcionamento | DA11: Dias de Funcionamento | DH11: Dias de Funcionamento | DO11: Dias de Funcionamento | DV11: Dias de Funcionamento | EC11: Dias de Funcionamento | EJ11: Dias de Funcionamento | EQ11: Dias de Funcionamento
N12: Nome do responsável | U12: Nome do responsável | AB12: Nome do responsável | AI12: Nome do responsável | AP12: Nome do responsável | AW12: Nome do responsável | BD12: Nome do responsável | BK12: Nome do responsável | BR12: Nome do responsável | BY12: Nome do responsável | CF12: Nome do responsável | CM12: Nome do responsável | CT12: Nome do responsável | DA12: Nome do responsável | DH12: Nome do responsável | DO12: Nome do responsável | DV12: Nome do responsável | EC12: Nome do responsável | EJ12: Nome do responsável | EQ12: Nome do responsável
N13: Telefone de contato | U13: Telefone de contato | AB13: Telefone de contato | AI13: Telefone de contato | AP13: Telefone de contato | AW13: Telefone de contato | BD13: Telefone de contato | BK13: Telefone de contato | BR13: Telefone de contato | BY13: Telefone de contato | CF13: Telefone de contato | CM13: Telefone de contato | CT13: Telefone de contato | DA13: Telefone de contato | DH13: Telefone de contato | DO13: Telefone de contato | DV13: Telefone de contato | EC13: Telefone de contato | EJ13: Telefone de contato | EQ13: Telefone de contato
N14: E-mail | U14: E-mail | AB14: E-mail | AI14: E-mail | AP14: E-mail | AW14: E-mail | BD14: E-mail | BK14: E-mail | BR14: E-mail | BY14: E-mail | CF14: E-mail | CM14: E-mail | CT14: E-mail | DA14: E-mail | DH14: E-mail | DO14: E-mail | DV14: E-mail | EC14: E-mail | EJ14: E-mail | EQ14: E-mail
N15: Número de fases do padrão de entrada | Q15: Selecione a quantidade de fases | U15: Número de fases do padrão de entrada | X15: Selecione a quantidade de fases | AB15: Número de fases do padrão de entrada | AE15: Selecione a quantidade de fases | AI15: Número de fases do padrão de entrada | AL15: Selecione a quantidade de fases | AP15: Número de fases do padrão de entrada | AS15: Selecione a quantidade de fases | AW15: Número de fases do padrão de entrada | AZ15: Selecione a quantidade de fases | BD15: Número de fases do padrão de entrada | BG15: Selecione a quantidade de fases | BK15: Número de fases do padrão de entrada | BN15: Selecione a quantidade de fases | BR15: Número de fases do padrão de entrada | BU15: Selecione a quantidade de fases | BY15: Número de fases do padrão de entrada | CB15: Selecione a quantidade de fases | CF15: Número de fases do padrão de entrada | CI15: Selecione a quantidade de fases | CM15: Número de fases do padrão de entrada | CP15: Selecione a quantidade de fases | CT15: Número de fases do padrão de entrada | CW15: Selecione a quantidade de fases | DA15: Número de fases do padrão de entrada | DD15: Selecione a quantidade de fases | DH15: Número de fases do padrão de entrada | DK15: Selecione a quantidade de fases | DO15: Número de fases do padrão de entrada | DR15: Selecione a quantidade de fases | DV15: Número de fases do padrão de entrada | DY15: Selecione a quantidade de fases | EC15: Número de fases do padrão de entrada | EF15: Selecione a quantidade de fases | EJ15: Número de fases do padrão de entrada | EM15: Selecione a quantidade de fases | EQ15: Número de fases do padrão de entrada | ET15: Selecione a quantidade de fases
N16: Subclasse tarifária | Q16: Selecione a subclasse tarifária | U16: Subclasse tarifária | X16: Selecione a subclasse tarifária | AB16: Subclasse tarifária | AE16: Selecione a subclasse tarifária | AI16: Subclasse tarifária | AL16: Selecione a subclasse tarifária | AP16: Subclasse tarifária | AS16: Selecione a subclasse tarifária | AW16: Subclasse tarifária | AZ16: Selecione a subclasse tarifária | BD16: Subclasse tarifária | BG16: Selecione a subclasse tarifária | BK16: Subclasse tarifária | BN16: Selecione a subclasse tarifária | BR16: Subclasse tarifária | BU16: Selecione a subclasse tarifária | BY16: Subclasse tarifária | CB16: Selecione a subclasse tarifária | CF16: Subclasse tarifária | CI16: Selecione a subclasse tarifária | CM16: Subclasse tarifária | CP16: Selecione a subclasse tarifária | CT16: Subclasse tarifária | CW16: Selecione a subclasse tarifária | DA16: Subclasse tarifária | DD16: Selecione a subclasse tarifária | DH16: Subclasse tarifária | DK16: Selecione a subclasse tarifária | DO16: Subclasse tarifária | DR16: Selecione a subclasse tarifária | DV16: Subclasse tarifária | DY16: Selecione a subclasse tarifária | EC16: Subclasse tarifária | EF16: Selecione a subclasse tarifária | EJ16: Subclasse tarifária | EM16: Selecione a subclasse tarifária | EQ16: Subclasse tarifária | ET16: Selecione a subclasse tarifária
N17: Modalidade Tarifária | Q17: Selecione a modalidade tarifária | U17: Modalidade Tarifária | X17: Selecione a modalidade tarifária | AB17: Modalidade Tarifária | AE17: Selecione a modalidade tarifária | AI17: Modalidade Tarifária | AL17: Selecione a modalidade tarifária | AP17: Modalidade Tarifária | AS17: Selecione a modalidade tarifária | AW17: Modalidade Tarifária | AZ17: Selecione a modalidade tarifária | BD17: Modalidade Tarifária | BG17: Selecione a modalidade tarifária | BK17: Modalidade Tarifária | BN17: Selecione a modalidade tarifária | BR17: Modalidade Tarifária | BU17: Selecione a modalidade tarifária | BY17: Modalidade Tarifária | CB17: Selecione a modalidade tarifária | CF17: Modalidade Tarifária | CI17: Selecione a modalidade tarifária | CM17: Modalidade Tarifária | CP17: Selecione a modalidade tarifária | CT17: Modalidade Tarifária | CW17: Selecione a modalidade tarifária | DA17: Modalidade Tarifária | DD17: Selecione a modalidade tarifária | DH17: Modalidade Tarifária | DK17: Selecione a modalidade tarifária | DO17: Modalidade Tarifária | DR17: Selecione a modalidade tarifária | DV17: Modalidade Tarifária | DY17: Selecione a modalidade tarifária | EC17: Modalidade Tarifária | EF17: Selecione a modalidade tarifária | EJ17: Modalidade Tarifária | EM17: Selecione a modalidade tarifária | EQ17: Modalidade Tarifária | ET17: Selecione a modalidade tarifária
N18: Ambiente de contratação de energia | Q18: Selecione o tipo de contratação | U18: Ambiente de contratação de energia | X18: Selecione o tipo de contratação | AB18: Ambiente de contratação de energia | AE18: Selecione o tipo de contratação | AI18: Ambiente de contratação de energia | AL18: Selecione o tipo de contratação | AP18: Ambiente de contratação de energia | AS18: Selecione o tipo de contratação | AW18: Ambiente de contratação de energia | AZ18: Selecione o tipo de contratação | BD18: Ambiente de contratação de energia | BG18: Selecione o tipo de contratação | BK18: Ambiente de contratação de energia | BN18: Selecione o tipo de contratação | BR18: Ambiente de contratação de energia | BU18: Selecione o tipo de contratação | BY18: Ambiente de contratação de energia | CB18: Selecione o tipo de contratação | CF18: Ambiente de contratação de energia | CI18: Selecione o tipo de contratação | CM18: Ambiente de contratação de energia | CP18: Selecione o tipo de contratação | CT18: Ambiente de contratação de energia | CW18: Selecione o tipo de contratação | DA18: Ambiente de contratação de energia | DD18: Selecione o tipo de contratação | DH18: Ambiente de contratação de energia | DK18: Selecione o tipo de contratação | DO18: Ambiente de contratação de energia | DR18: Selecione o tipo de contratação | DV18: Ambiente de contratação de energia | DY18: Selecione o tipo de contratação | EC18: Ambiente de contratação de energia | EF18: Selecione o tipo de contratação | EJ18: Ambiente de contratação de energia | EM18: Selecione o tipo de contratação | EQ18: Ambiente de contratação de energia | ET18: Selecione o tipo de contratação
N19: Possui sistema fotovoltaico? Se sim, inserir potência total instalada (kW) | U19: Possui sistema fotovoltaico? Se sim, inserir potência total instalada (kW) | AB19: Possui sistema fotovoltaico? Se sim, inserir potência total instalada (kW) | AI19: Possui sistema fotovoltaico? Se sim, inserir potência total instalada (kW) | AP19: Possui sistema fotovoltaico? Se sim, inserir potência total instalada (kW) | AW19: Possui sistema fotovoltaico? Se sim, inserir potência total instalada (kW) | BD19: Possui sistema fotovoltaico? Se sim, inserir potência total instalada (kW) | BK19: Possui sistema fotovoltaico? Se sim, inserir potência total instalada (kW) | BR19: Possui sistema fotovoltaico? Se sim, inserir potência total instalada (kW) | BY19: Possui sistema fotovoltaico? Se sim, inserir potência total instalada (kW) | CF19: Possui sistema fotovoltaico? Se sim, inserir potência total instalada (kW) | CM19: Possui sistema fotovoltaico? Se sim, inserir potência total instalada (kW) | CT19: Possui sistema fotovoltaico? Se sim, inserir potência total instalada (kW) | DA19: Possui sistema fotovoltaico? Se sim, inserir potência total instalada (kW) | DH19: Possui sistema fotovoltaico? Se sim, inserir potência total instalada (kW) | DO19: Possui sistema fotovoltaico? Se sim, inserir potência total instalada (kW) | DV19: Possui sistema fotovoltaico? Se sim, inserir potência total instalada (kW) | EC19: Possui sistema fotovoltaico? Se sim, inserir potência total instalada (kW) | EJ19: Possui sistema fotovoltaico? Se sim, inserir potência total instalada (kW) | EQ19: Possui sistema fotovoltaico? Se sim, inserir potência total instalada (kW)
N20: Ramo de Atividade | U20: Ramo de Atividade | AB20: Ramo de Atividade | AI20: Ramo de Atividade | AP20: Ramo de Atividade | AW20: Ramo de Atividade | BD20: Ramo de Atividade | BK20: Ramo de Atividade | BR20: Ramo de Atividade | BY20: Ramo de Atividade | CF20: Ramo de Atividade | CM20: Ramo de Atividade | CT20: Ramo de Atividade | DA20: Ramo de Atividade | DH20: Ramo de Atividade | DO20: Ramo de Atividade | DV20: Ramo de Atividade | EC20: Ramo de Atividade | EJ20: Ramo de Atividade | EQ20: Ramo de Atividade
B22: LISTA DAS UNIDADES CONSUMIDORAS DO PROJETO | F22: CONSUMO GLOBAL | N22: 1 - CONSUMO DA UC: | Q22: =R2 -> 0 | U22: 2 - CONSUMO DA UC: | X22: =Y2 -> 0 | AB22: 3 - CONSUMO DA UC: | AE22: =AF2 -> 0 | AI22: 4 - CONSUMO DA UC: | AL22: =AM2 -> 0 | AP22: 5 - CONSUMO DA UC: | AS22: =AT2 -> 0 | AW22: 6 - CONSUMO DA UC: | AZ22: =BA2 -> 0 | BD22: 7 - CONSUMO DA UC: | BG22: =BH2 -> 0 | BK22: 8 - CONSUMO DA UC: | BN22: =BO2 -> 0 | BR22: 9 - CONSUMO DA UC: | BU22: =BV2 -> 0 | BY22: 10 - CONSUMO DA UC: | CB22: =CC2 -> 0 | CF22: 11 - CONSUMO DA UC: | CI22: =CJ2 -> 0 | CM22: 12 - CONSUMO DA UC: | CP22: =CQ2 -> 0 | CT22: 13 - CONSUMO DA UC: | CW22: =CX2 -> 0 | DA22: 14 - CONSUMO DA UC: | DD22: =DE2 -> 0 | DH22: 15 - CONSUMO DA UC: | DK22: =DL2 -> 0 | DO22: 16 - CONSUMO DA UC: | DR22: =DS2 -> 0 | DV22: 17 - CONSUMO DA UC: | DY22: =DZ2 -> 0 | EC22: 18 - CONSUMO DA UC: | EF22: =EG2 -> 0 | EJ22: 19 - CONSUMO DA UC: | EM22: =EN2 -> 0 | EQ22: 20 - CONSUMO DA UC: | ET22: =EU2 -> 0
B23: Nº | C23: Nº da Unidade Consumidora | D23: Identificação | F23: Mês/Ano | G23: Demanda Ponta (kW) | H23: Demanda Fora Ponta (kW) | I23: Consumo Ponta (kWh/mês) | J23: Consumo Fora Ponta (kWh/mês) | K23: Consumo Total (kWh/mês) | M23: Mês | N23: Mês/Ano | O23: Demanda Ponta (kW) | P23: Demanda Fora Ponta (kW) | Q23: Consumo Ponta (kWh/mês) | R23: Consumo Fora Ponta (kWh/mês) | S23: Consumo Total (kWh/mês) | U23: Mês/Ano | V23: Demanda Ponta (kW) | W23: Demanda Fora Ponta (kW) | X23: Consumo Ponta (kWh/mês) | Y23: Consumo Fora Ponta (kWh/mês) | Z23: Consumo Total (kWh/mês) | AB23: Mês/Ano | AC23: Demanda Ponta (kW) | AD23: Demanda Fora Ponta (kW) | AE23: Consumo Ponta (kWh/mês) | AF23: Consumo Fora Ponta (kWh/mês) | AG23: Consumo Total (kWh/mês) | AI23: Mês/Ano | AJ23: Demanda Ponta (kW) | AK23: Demanda Fora Ponta (kW) | AL23: Consumo Ponta (kWh/mês) | AM23: Consumo Fora Ponta (kWh/mês) | AN23: Consumo Total (kWh/mês) | AP23: Mês/Ano | AQ23: Demanda Ponta (kW) | AR23: Demanda Fora Ponta (kW) | AS23: Consumo Ponta (kWh/mês) | AT23: Consumo Fora Ponta (kWh/mês) | AU23: Consumo Total (kWh/mês) | AW23: Mês/Ano | AX23: Demanda Ponta (kW) | AY23: Demanda Fora Ponta (kW) | AZ23: Consumo Ponta (kWh/mês) | BA23: Consumo Fora Ponta (kWh/mês) | BB23: Consumo Total (kWh/mês) | BD23: Mês/Ano | BE23: Demanda Ponta (kW) | BF23: Demanda Fora Ponta (kW) | BG23: Consumo Ponta (kWh/mês) | BH23: Consumo Fora Ponta (kWh/mês) | BI23: Consumo Total (kWh/mês) | BK23: Mês/Ano | BL23: Demanda Ponta (kW) | BM23: Demanda Fora Ponta (kW) | BN23: Consumo Ponta (kWh/mês) | BO23: Consumo Fora Ponta (kWh/mês) | BP23: Consumo Total (kWh/mês) | BR23: Mês/Ano | BS23: Demanda Ponta (kW) | BT23: Demanda Fora Ponta (kW) | BU23: Consumo Ponta (kWh/mês) | BV23: Consumo Fora Ponta (kWh/mês) | BW23: Consumo Total (kWh/mês) | BY23: Mês/Ano | BZ23: Demanda Ponta (kW) | CA23: Demanda Fora Ponta (kW) | CB23: Consumo Ponta (kWh/mês) | CC23: Consumo Fora Ponta (kWh/mês) | CD23: Consumo Total (kWh/mês) | CF23: Mês/Ano | CG23: Demanda Ponta (kW) | CH23: Demanda Fora Ponta (kW) | CI23: Consumo Ponta (kWh/mês) | CJ23: Consumo Fora Ponta (kWh/mês) | CK23: Consumo Total (kWh/mês) | CM23: Mês/Ano | CN23: Demanda Ponta (kW) | CO23: Demanda Fora Ponta (kW) | CP23: Consumo Ponta (kWh/mês) | CQ23: Consumo Fora Ponta (kWh/mês) | CR23: Consumo Total (kWh/mês) | CT23: Mês/Ano | CU23: Demanda Ponta (kW) | CV23: Demanda Fora Ponta (kW) | CW23: Consumo Ponta (kWh/mês) | CX23: Consumo Fora Ponta (kWh/mês) | CY23: Consumo Total (kWh/mês) | DA23: Mês/Ano | DB23: Demanda Ponta (kW) | DC23: Demanda Fora Ponta (kW) | DD23: Consumo Ponta (kWh/mês) | DE23: Consumo Fora Ponta (kWh/mês) | DF23: Consumo Total (kWh/mês) | DH23: Mês/Ano | DI23: Demanda Ponta (kW) | DJ23: Demanda Fora Ponta (kW) | DK23: Consumo Ponta (kWh/mês) | DL23: Consumo Fora Ponta (kWh/mês) | DM23: Consumo Total (kWh/mês) | DO23: Mês/Ano | DP23: Demanda Ponta (kW) | DQ23: Demanda Fora Ponta (kW) | DR23: Consumo Ponta (kWh/mês) | DS23: Consumo Fora Ponta (kWh/mês) | DT23: Consumo Total (kWh/mês) | DV23: Mês/Ano | DW23: Demanda Ponta (kW) | DX23: Demanda Fora Ponta (kW) | DY23: Consumo Ponta (kWh/mês) | DZ23: Consumo Fora Ponta (kWh/mês) | EA23: Consumo Total (kWh/mês) | EC23: Mês/Ano | ED23: Demanda Ponta (kW) | EE23: Demanda Fora Ponta (kW) | EF23: Consumo Ponta (kWh/mês) | EG23: Consumo Fora Ponta (kWh/mês) | EH23: Consumo Total (kWh/mês) | EJ23: Mês/Ano | EK23: Demanda Ponta (kW) | EL23: Demanda Fora Ponta (kW) | EM23: Consumo Ponta (kWh/mês) | EN23: Consumo Fora Ponta (kWh/mês) | EO23: Consumo Total (kWh/mês) | EQ23: Mês/Ano | ER23: Demanda Ponta (kW) | ES23: Demanda Fora Ponta (kW) | ET23: Consumo Ponta (kWh/mês) | EU23: Consumo Fora Ponta (kWh/mês) | EV23: Consumo Total (kWh/mês)
B24: 1 | C24: =IF(R2<>"",R2,"") | D24: =IF(Q3<>"",Q3,"") | F24: =IF($N$24="","",$N$24) | G24: =O24+V24+AC24+AJ24+AQ24+AX24+BE24+BL24+BS24+BZ24+CG24+CN24+CU24+DB24+DI24+DP24+DW24+ED24+EK24+ER24 -> 0 | H24: =P24+W24+AD24+AK24+AR24+AY24+BF24+BM24+BT24+CA24+CH24+CO24+CV24+DC24+DJ24+DQ24+DX24+EE24+EL24+ES24 -> 0 | I24: =Q24+X24+AE24+AL24+AS24+AZ24+BG24+BN24+BU24+CB24+CI24+CP24+CW24+DD24+DK24+DR24+DY24+EF24+EM24+ET24 -> 0 | J24: =R24+Y24+AF24+AM24+AT24+BA24+BH24+BO24+BV24+CC24+CJ24+CQ24+CX24+DE24+DL24+DS24+DZ24+EG24+EN24+EU24 -> 0 | K24: =S24+Z24+AG24+AN24+AU24+BB24+BI24+BP24+BW24+CD24+CK24+CR24+CY24+DF24+DM24+DT24+EA24+EH24+EO24+EV24 -> 0 | M24: 1 | S24: =Q24+R24 -> 0 | U24: =IF($N$24="","",$N$24) | Z24: =X24+Y24 -> 0 | AB24: =IF($N$24="","",$N$24) | AG24: =AE24+AF24 -> 0 | AI24: =IF($N$24="","",$N$24) | AN24: =AL24+AM24 -> 0 | AP24: =IF($N$24="","",$N$24) | AU24: =AS24+AT24 -> 0 | AW24: =IF($N$24="","",$N$24) | BB24: =AZ24+BA24 -> 0 | BD24: =IF($N$24="","",$N$24) | BI24: =BG24+BH24 -> 0 | BK24: =IF($N$24="","",$N$24) | BP24: =BN24+BO24 -> 0 | BR24: =IF($N$24="","",$N$24) | BW24: =BU24+BV24 -> 0 | BY24: =IF($N$24="","",$N$24) | CD24: =CB24+CC24 -> 0 | CF24: =IF($N$24="","",$N$24) | CK24: =CI24+CJ24 -> 0 | CM24: =IF($N$24="","",$N$24) | CR24: =CP24+CQ24 -> 0 | CT24: =IF($N$24="","",$N$24) | CY24: =CW24+CX24 -> 0 | DA24: =IF($N$24="","",$N$24) | DF24: =DD24+DE24 -> 0 | DH24: =IF($N$24="","",$N$24) | DM24: =DK24+DL24 -> 0 | DO24: =IF($N$24="","",$N$24) | DT24: =DR24+DS24 -> 0 | DV24: =IF($N$24="","",$N$24) | EA24: =DY24+DZ24 -> 0 | EC24: =IF($N$24="","",$N$24) | EH24: =EF24+EG24 -> 0 | EJ24: =IF($N$24="","",$N$24) | EO24: =EM24+EN24 -> 0 | EQ24: =IF($N$24="","",$N$24) | EV24: =ET24+EU24 -> 0
B25: 2 | C25: =IF(Y2<>"",Y2,"") | D25: =IF(X3<>"",X3,"") | F25: =IF($N$25="","",$N$25) | G25: =O25+V25+AC25+AJ25+AQ25+AX25+BE25+BL25+BS25+BZ25+CG25+CN25+CU25+DB25+DI25+DP25+DW25+ED25+EK25+ER25 -> 0 | H25: =P25+W25+AD25+AK25+AR25+AY25+BF25+BM25+BT25+CA25+CH25+CO25+CV25+DC25+DJ25+DQ25+DX25+EE25+EL25+ES25 -> 0 | I25: =Q25+X25+AE25+AL25+AS25+AZ25+BG25+BN25+BU25+CB25+CI25+CP25+CW25+DD25+DK25+DR25+DY25+EF25+EM25+ET25 -> 0 | J25: =R25+Y25+AF25+AM25+AT25+BA25+BH25+BO25+BV25+CC25+CJ25+CQ25+CX25+DE25+DL25+DS25+DZ25+EG25+EN25+EU25 -> 0 | K25: =S25+Z25+AG25+AN25+AU25+BB25+BI25+BP25+BW25+CD25+CK25+CR25+CY25+DF25+DM25+DT25+EA25+EH25+EO25+EV25 -> 0 | M25: 2 | S25: =Q25+R25 -> 0 | U25: =IF($N$25="","",$N$25) | Z25: =X25+Y25 -> 0 | AB25: =IF($N$25="","",$N$25) | AG25: =AE25+AF25 -> 0 | AI25: =IF($N$25="","",$N$25) | AN25: =AL25+AM25 -> 0 | AP25: =IF($N$25="","",$N$25) | AU25: =AS25+AT25 -> 0 | AW25: =IF($N$25="","",$N$25) | BB25: =AZ25+BA25 -> 0 | BD25: =IF($N$25="","",$N$25) | BI25: =BG25+BH25 -> 0 | BK25: =IF($N$25="","",$N$25) | BP25: =BN25+BO25 -> 0 | BR25: =IF($N$25="","",$N$25) | BW25: =BU25+BV25 -> 0 | BY25: =IF($N$25="","",$N$25) | CD25: =CB25+CC25 -> 0 | CF25: =IF($N$25="","",$N$25) | CK25: =CI25+CJ25 -> 0 | CM25: =IF($N$25="","",$N$25) | CR25: =CP25+CQ25 -> 0 | CT25: =IF($N$25="","",$N$25) | CY25: =CW25+CX25 -> 0 | DA25: =IF($N$25="","",$N$25) | DF25: =DD25+DE25 -> 0 | DH25: =IF($N$25="","",$N$25) | DM25: =DK25+DL25 -> 0 | DO25: =IF($N$25="","",$N$25) | DT25: =DR25+DS25 -> 0 | DV25: =IF($N$25="","",$N$25) | EA25: =DY25+DZ25 -> 0 | EC25: =IF($N$25="","",$N$25) | EH25: =EF25+EG25 -> 0 | EJ25: =IF($N$25="","",$N$25) | EO25: =EM25+EN25 -> 0 | EQ25: =IF($N$25="","",$N$25) | EV25: =ET25+EU25 -> 0
B26: 3 | C26: =IF(AF2<>"",AF2,"") | D26: =IF(AE3<>"",AE3,"") | F26: =IF($N$26="","",$N$26) | G26: =O26+V26+AC26+AJ26+AQ26+AX26+BE26+BL26+BS26+BZ26+CG26+CN26+CU26+DB26+DI26+DP26+DW26+ED26+EK26+ER26 -> 0 | H26: =P26+W26+AD26+AK26+AR26+AY26+BF26+BM26+BT26+CA26+CH26+CO26+CV26+DC26+DJ26+DQ26+DX26+EE26+EL26+ES26 -> 0 | I26: =Q26+X26+AE26+AL26+AS26+AZ26+BG26+BN26+BU26+CB26+CI26+CP26+CW26+DD26+DK26+DR26+DY26+EF26+EM26+ET26 -> 0 | J26: =R26+Y26+AF26+AM26+AT26+BA26+BH26+BO26+BV26+CC26+CJ26+CQ26+CX26+DE26+DL26+DS26+DZ26+EG26+EN26+EU26 -> 0 | K26: =S26+Z26+AG26+AN26+AU26+BB26+BI26+BP26+BW26+CD26+CK26+CR26+CY26+DF26+DM26+DT26+EA26+EH26+EO26+EV26 -> 0 | M26: 3 | S26: =Q26+R26 -> 0 | U26: =IF($N$26="","",$N$26) | Z26: =X26+Y26 -> 0 | AB26: =IF($N$26="","",$N$26) | AG26: =AE26+AF26 -> 0 | AI26: =IF($N$26="","",$N$26) | AN26: =AL26+AM26 -> 0 | AP26: =IF($N$26="","",$N$26) | AU26: =AS26+AT26 -> 0 | AW26: =IF($N$26="","",$N$26) | BB26: =AZ26+BA26 -> 0 | BD26: =IF($N$26="","",$N$26) | BI26: =BG26+BH26 -> 0 | BK26: =IF($N$26="","",$N$26) | BP26: =BN26+BO26 -> 0 | BR26: =IF($N$26="","",$N$26) | BW26: =BU26+BV26 -> 0 | BY26: =IF($N$26="","",$N$26) | CD26: =CB26+CC26 -> 0 | CF26: =IF($N$26="","",$N$26) | CK26: =CI26+CJ26 -> 0 | CM26: =IF($N$26="","",$N$26) | CR26: =CP26+CQ26 -> 0 | CT26: =IF($N$26="","",$N$26) | CY26: =CW26+CX26 -> 0 | DA26: =IF($N$26="","",$N$26) | DF26: =DD26+DE26 -> 0 | DH26: =IF($N$26="","",$N$26) | DM26: =DK26+DL26 -> 0 | DO26: =IF($N$26="","",$N$26) | DT26: =DR26+DS26 -> 0 | DV26: =IF($N$26="","",$N$26) | EA26: =DY26+DZ26 -> 0 | EC26: =IF($N$26="","",$N$26) | EH26: =EF26+EG26 -> 0 | EJ26: =IF($N$26="","",$N$26) | EO26: =EM26+EN26 -> 0 | EQ26: =IF($N$26="","",$N$26) | EV26: =ET26+EU26 -> 0
B27: 4 | C27: =IF(AM2<>"",AM2,"") | D27: =IF(AL3<>"",AL3,"") | F27: =IF($N$27="","",$N$27) | G27: =O27+V27+AC27+AJ27+AQ27+AX27+BE27+BL27+BS27+BZ27+CG27+CN27+CU27+DB27+DI27+DP27+DW27+ED27+EK27+ER27 -> 0 | H27: =P27+W27+AD27+AK27+AR27+AY27+BF27+BM27+BT27+CA27+CH27+CO27+CV27+DC27+DJ27+DQ27+DX27+EE27+EL27+ES27 -> 0 | I27: =Q27+X27+AE27+AL27+AS27+AZ27+BG27+BN27+BU27+CB27+CI27+CP27+CW27+DD27+DK27+DR27+DY27+EF27+EM27+ET27 -> 0 | J27: =R27+Y27+AF27+AM27+AT27+BA27+BH27+BO27+BV27+CC27+CJ27+CQ27+CX27+DE27+DL27+DS27+DZ27+EG27+EN27+EU27 -> 0 | K27: =S27+Z27+AG27+AN27+AU27+BB27+BI27+BP27+BW27+CD27+CK27+CR27+CY27+DF27+DM27+DT27+EA27+EH27+EO27+EV27 -> 0 | M27: 4 | S27: =Q27+R27 -> 0 | U27: =IF($N$27="","",$N$27) | Z27: =X27+Y27 -> 0 | AB27: =IF($N$27="","",$N$27) | AG27: =AE27+AF27 -> 0 | AI27: =IF($N$27="","",$N$27) | AN27: =AL27+AM27 -> 0 | AP27: =IF($N$27="","",$N$27) | AU27: =AS27+AT27 -> 0 | AW27: =IF($N$27="","",$N$27) | BB27: =AZ27+BA27 -> 0 | BD27: =IF($N$27="","",$N$27) | BI27: =BG27+BH27 -> 0 | BK27: =IF($N$27="","",$N$27) | BP27: =BN27+BO27 -> 0 | BR27: =IF($N$27="","",$N$27) | BW27: =BU27+BV27 -> 0 | BY27: =IF($N$27="","",$N$27) | CD27: =CB27+CC27 -> 0 | CF27: =IF($N$27="","",$N$27) | CK27: =CI27+CJ27 -> 0 | CM27: =IF($N$27="","",$N$27) | CR27: =CP27+CQ27 -> 0 | CT27: =IF($N$27="","",$N$27) | CY27: =CW27+CX27 -> 0 | DA27: =IF($N$27="","",$N$27) | DF27: =DD27+DE27 -> 0 | DH27: =IF($N$27="","",$N$27) | DM27: =DK27+DL27 -> 0 | DO27: =IF($N$27="","",$N$27) | DT27: =DR27+DS27 -> 0 | DV27: =IF($N$27="","",$N$27) | EA27: =DY27+DZ27 -> 0 | EC27: =IF($N$27="","",$N$27) | EH27: =EF27+EG27 -> 0 | EJ27: =IF($N$27="","",$N$27) | EO27: =EM27+EN27 -> 0 | EQ27: =IF($N$27="","",$N$27) | EV27: =ET27+EU27 -> 0
B28: 5 | C28: =IF(AT2<>"",AT2,"") | D28: =IF(AS3<>"",AS3,"") | F28: =IF($N$28="","",$N$28) | G28: =O28+V28+AC28+AJ28+AQ28+AX28+BE28+BL28+BS28+BZ28+CG28+CN28+CU28+DB28+DI28+DP28+DW28+ED28+EK28+ER28 -> 0 | H28: =P28+W28+AD28+AK28+AR28+AY28+BF28+BM28+BT28+CA28+CH28+CO28+CV28+DC28+DJ28+DQ28+DX28+EE28+EL28+ES28 -> 0 | I28: =Q28+X28+AE28+AL28+AS28+AZ28+BG28+BN28+BU28+CB28+CI28+CP28+CW28+DD28+DK28+DR28+DY28+EF28+EM28+ET28 -> 0 | J28: =R28+Y28+AF28+AM28+AT28+BA28+BH28+BO28+BV28+CC28+CJ28+CQ28+CX28+DE28+DL28+DS28+DZ28+EG28+EN28+EU28 -> 0 | K28: =S28+Z28+AG28+AN28+AU28+BB28+BI28+BP28+BW28+CD28+CK28+CR28+CY28+DF28+DM28+DT28+EA28+EH28+EO28+EV28 -> 0 | M28: 5 | S28: =Q28+R28 -> 0 | U28: =IF($N$28="","",$N$28) | Z28: =X28+Y28 -> 0 | AB28: =IF($N$28="","",$N$28) | AG28: =AE28+AF28 -> 0 | AI28: =IF($N$28="","",$N$28) | AN28: =AL28+AM28 -> 0 | AP28: =IF($N$28="","",$N$28) | AU28: =AS28+AT28 -> 0 | AW28: =IF($N$28="","",$N$28) | BB28: =AZ28+BA28 -> 0 | BD28: =IF($N$28="","",$N$28) | BI28: =BG28+BH28 -> 0 | BK28: =IF($N$28="","",$N$28) | BP28: =BN28+BO28 -> 0 | BR28: =IF($N$28="","",$N$28) | BW28: =BU28+BV28 -> 0 | BY28: =IF($N$28="","",$N$28) | CD28: =CB28+CC28 -> 0 | CF28: =IF($N$28="","",$N$28) | CK28: =CI28+CJ28 -> 0 | CM28: =IF($N$28="","",$N$28) | CR28: =CP28+CQ28 -> 0 | CT28: =IF($N$28="","",$N$28) | CY28: =CW28+CX28 -> 0 | DA28: =IF($N$28="","",$N$28) | DF28: =DD28+DE28 -> 0 | DH28: =IF($N$28="","",$N$28) | DM28: =DK28+DL28 -> 0 | DO28: =IF($N$28="","",$N$28) | DT28: =DR28+DS28 -> 0 | DV28: =IF($N$28="","",$N$28) | EA28: =DY28+DZ28 -> 0 | EC28: =IF($N$28="","",$N$28) | EH28: =EF28+EG28 -> 0 | EJ28: =IF($N$28="","",$N$28) | EO28: =EM28+EN28 -> 0 | EQ28: =IF($N$28="","",$N$28) | EV28: =ET28+EU28 -> 0
B29: 6 | C29: =IF(BA2<>"",BA2,"") | D29: =IF(AZ3<>"",AZ3,"") | F29: =IF($N$29="","",$N$29) | G29: =O29+V29+AC29+AJ29+AQ29+AX29+BE29+BL29+BS29+BZ29+CG29+CN29+CU29+DB29+DI29+DP29+DW29+ED29+EK29+ER29 -> 0 | H29: =P29+W29+AD29+AK29+AR29+AY29+BF29+BM29+BT29+CA29+CH29+CO29+CV29+DC29+DJ29+DQ29+DX29+EE29+EL29+ES29 -> 0 | I29: =Q29+X29+AE29+AL29+AS29+AZ29+BG29+BN29+BU29+CB29+CI29+CP29+CW29+DD29+DK29+DR29+DY29+EF29+EM29+ET29 -> 0 | J29: =R29+Y29+AF29+AM29+AT29+BA29+BH29+BO29+BV29+CC29+CJ29+CQ29+CX29+DE29+DL29+DS29+DZ29+EG29+EN29+EU29 -> 0 | K29: =S29+Z29+AG29+AN29+AU29+BB29+BI29+BP29+BW29+CD29+CK29+CR29+CY29+DF29+DM29+DT29+EA29+EH29+EO29+EV29 -> 0 | M29: 6 | S29: =Q29+R29 -> 0 | U29: =IF($N$29="","",$N$29) | Z29: =X29+Y29 -> 0 | AB29: =IF($N$29="","",$N$29) | AG29: =AE29+AF29 -> 0 | AI29: =IF($N$29="","",$N$29) | AN29: =AL29+AM29 -> 0 | AP29: =IF($N$29="","",$N$29) | AU29: =AS29+AT29 -> 0 | AW29: =IF($N$29="","",$N$29) | BB29: =AZ29+BA29 -> 0 | BD29: =IF($N$29="","",$N$29) | BI29: =BG29+BH29 -> 0 | BK29: =IF($N$29="","",$N$29) | BP29: =BN29+BO29 -> 0 | BR29: =IF($N$29="","",$N$29) | BW29: =BU29+BV29 -> 0 | BY29: =IF($N$29="","",$N$29) | CD29: =CB29+CC29 -> 0 | CF29: =IF($N$29="","",$N$29) | CK29: =CI29+CJ29 -> 0 | CM29: =IF($N$29="","",$N$29) | CR29: =CP29+CQ29 -> 0 | CT29: =IF($N$29="","",$N$29) | CY29: =CW29+CX29 -> 0 | DA29: =IF($N$29="","",$N$29) | DF29: =DD29+DE29 -> 0 | DH29: =IF($N$29="","",$N$29) | DM29: =DK29+DL29 -> 0 | DO29: =IF($N$29="","",$N$29) | DT29: =DR29+DS29 -> 0 | DV29: =IF($N$29="","",$N$29) | EA29: =DY29+DZ29 -> 0 | EC29: =IF($N$29="","",$N$29) | EH29: =EF29+EG29 -> 0 | EJ29: =IF($N$29="","",$N$29) | EO29: =EM29+EN29 -> 0 | EQ29: =IF($N$29="","",$N$29) | EV29: =ET29+EU29 -> 0
B30: 7 | C30: =IF(BH2<>"",BH2,"") | D30: =IF(BG3<>"",BG3,"") | F30: =IF($N$30="","",$N$30) | G30: =O30+V30+AC30+AJ30+AQ30+AX30+BE30+BL30+BS30+BZ30+CG30+CN30+CU30+DB30+DI30+DP30+DW30+ED30+EK30+ER30 -> 0 | H30: =P30+W30+AD30+AK30+AR30+AY30+BF30+BM30+BT30+CA30+CH30+CO30+CV30+DC30+DJ30+DQ30+DX30+EE30+EL30+ES30 -> 0 | I30: =Q30+X30+AE30+AL30+AS30+AZ30+BG30+BN30+BU30+CB30+CI30+CP30+CW30+DD30+DK30+DR30+DY30+EF30+EM30+ET30 -> 0 | J30: =R30+Y30+AF30+AM30+AT30+BA30+BH30+BO30+BV30+CC30+CJ30+CQ30+CX30+DE30+DL30+DS30+DZ30+EG30+EN30+EU30 -> 0 | K30: =S30+Z30+AG30+AN30+AU30+BB30+BI30+BP30+BW30+CD30+CK30+CR30+CY30+DF30+DM30+DT30+EA30+EH30+EO30+EV30 -> 0 | M30: 7 | S30: =Q30+R30 -> 0 | U30: =IF($N$30="","",$N$30) | Z30: =X30+Y30 -> 0 | AB30: =IF($N$30="","",$N$30) | AG30: =AE30+AF30 -> 0 | AI30: =IF($N$30="","",$N$30) | AN30: =AL30+AM30 -> 0 | AP30: =IF($N$30="","",$N$30) | AU30: =AS30+AT30 -> 0 | AW30: =IF($N$30="","",$N$30) | BB30: =AZ30+BA30 -> 0 | BD30: =IF($N$30="","",$N$30) | BI30: =BG30+BH30 -> 0 | BK30: =IF($N$30="","",$N$30) | BP30: =BN30+BO30 -> 0 | BR30: =IF($N$30="","",$N$30) | BW30: =BU30+BV30 -> 0 | BY30: =IF($N$30="","",$N$30) | CD30: =CB30+CC30 -> 0 | CF30: =IF($N$30="","",$N$30) | CK30: =CI30+CJ30 -> 0 | CM30: =IF($N$30="","",$N$30) | CR30: =CP30+CQ30 -> 0 | CT30: =IF($N$30="","",$N$30) | CY30: =CW30+CX30 -> 0 | DA30: =IF($N$30="","",$N$30) | DF30: =DD30+DE30 -> 0 | DH30: =IF($N$30="","",$N$30) | DM30: =DK30+DL30 -> 0 | DO30: =IF($N$30="","",$N$30) | DT30: =DR30+DS30 -> 0 | DV30: =IF($N$30="","",$N$30) | EA30: =DY30+DZ30 -> 0 | EC30: =IF($N$30="","",$N$30) | EH30: =EF30+EG30 -> 0 | EJ30: =IF($N$30="","",$N$30) | EO30: =EM30+EN30 -> 0 | EQ30: =IF($N$30="","",$N$30) | EV30: =ET30+EU30 -> 0
B31: 8 | C31: =IF(BO2<>"",BO2,"") | D31: =IF(BN3<>"",BN3,"") | F31: =IF($N$31="","",$N$31) | G31: =O31+V31+AC31+AJ31+AQ31+AX31+BE31+BL31+BS31+BZ31+CG31+CN31+CU31+DB31+DI31+DP31+DW31+ED31+EK31+ER31 -> 0 | H31: =P31+W31+AD31+AK31+AR31+AY31+BF31+BM31+BT31+CA31+CH31+CO31+CV31+DC31+DJ31+DQ31+DX31+EE31+EL31+ES31 -> 0 | I31: =Q31+X31+AE31+AL31+AS31+AZ31+BG31+BN31+BU31+CB31+CI31+CP31+CW31+DD31+DK31+DR31+DY31+EF31+EM31+ET31 -> 0 | J31: =R31+Y31+AF31+AM31+AT31+BA31+BH31+BO31+BV31+CC31+CJ31+CQ31+CX31+DE31+DL31+DS31+DZ31+EG31+EN31+EU31 -> 0 | K31: =S31+Z31+AG31+AN31+AU31+BB31+BI31+BP31+BW31+CD31+CK31+CR31+CY31+DF31+DM31+DT31+EA31+EH31+EO31+EV31 -> 0 | M31: 8 | S31: =Q31+R31 -> 0 | U31: =IF($N$31="","",$N$31) | Z31: =X31+Y31 -> 0 | AB31: =IF($N$31="","",$N$31) | AG31: =AE31+AF31 -> 0 | AI31: =IF($N$31="","",$N$31) | AN31: =AL31+AM31 -> 0 | AP31: =IF($N$31="","",$N$31) | AU31: =AS31+AT31 -> 0 | AW31: =IF($N$31="","",$N$31) | BB31: =AZ31+BA31 -> 0 | BD31: =IF($N$31="","",$N$31) | BI31: =BG31+BH31 -> 0 | BK31: =IF($N$31="","",$N$31) | BP31: =BN31+BO31 -> 0 | BR31: =IF($N$31="","",$N$31) | BW31: =BU31+BV31 -> 0 | BY31: =IF($N$31="","",$N$31) | CD31: =CB31+CC31 -> 0 | CF31: =IF($N$31="","",$N$31) | CK31: =CI31+CJ31 -> 0 | CM31: =IF($N$31="","",$N$31) | CR31: =CP31+CQ31 -> 0 | CT31: =IF($N$31="","",$N$31) | CY31: =CW31+CX31 -> 0 | DA31: =IF($N$31="","",$N$31) | DF31: =DD31+DE31 -> 0 | DH31: =IF($N$31="","",$N$31) | DM31: =DK31+DL31 -> 0 | DO31: =IF($N$31="","",$N$31) | DT31: =DR31+DS31 -> 0 | DV31: =IF($N$31="","",$N$31) | EA31: =DY31+DZ31 -> 0 | EC31: =IF($N$31="","",$N$31) | EH31: =EF31+EG31 -> 0 | EJ31: =IF($N$31="","",$N$31) | EO31: =EM31+EN31 -> 0 | EQ31: =IF($N$31="","",$N$31) | EV31: =ET31+EU31 -> 0
B32: 9 | C32: =IF(BV2<>"",BV2,"") | D32: =IF(BU3<>"",BU3,"") | F32: =IF($N$32="","",$N$32) | G32: =O32+V32+AC32+AJ32+AQ32+AX32+BE32+BL32+BS32+BZ32+CG32+CN32+CU32+DB32+DI32+DP32+DW32+ED32+EK32+ER32 -> 0 | H32: =P32+W32+AD32+AK32+AR32+AY32+BF32+BM32+BT32+CA32+CH32+CO32+CV32+DC32+DJ32+DQ32+DX32+EE32+EL32+ES32 -> 0 | I32: =Q32+X32+AE32+AL32+AS32+AZ32+BG32+BN32+BU32+CB32+CI32+CP32+CW32+DD32+DK32+DR32+DY32+EF32+EM32+ET32 -> 0 | J32: =R32+Y32+AF32+AM32+AT32+BA32+BH32+BO32+BV32+CC32+CJ32+CQ32+CX32+DE32+DL32+DS32+DZ32+EG32+EN32+EU32 -> 0 | K32: =S32+Z32+AG32+AN32+AU32+BB32+BI32+BP32+BW32+CD32+CK32+CR32+CY32+DF32+DM32+DT32+EA32+EH32+EO32+EV32 -> 0 | M32: 9 | S32: =Q32+R32 -> 0 | U32: =IF($N$32="","",$N$32) | Z32: =X32+Y32 -> 0 | AB32: =IF($N$32="","",$N$32) | AG32: =AE32+AF32 -> 0 | AI32: =IF($N$32="","",$N$32) | AN32: =AL32+AM32 -> 0 | AP32: =IF($N$32="","",$N$32) | AU32: =AS32+AT32 -> 0 | AW32: =IF($N$32="","",$N$32) | BB32: =AZ32+BA32 -> 0 | BD32: =IF($N$32="","",$N$32) | BI32: =BG32+BH32 -> 0 | BK32: =IF($N$32="","",$N$32) | BP32: =BN32+BO32 -> 0 | BR32: =IF($N$32="","",$N$32) | BW32: =BU32+BV32 -> 0 | BY32: =IF($N$32="","",$N$32) | CD32: =CB32+CC32 -> 0 | CF32: =IF($N$32="","",$N$32) | CK32: =CI32+CJ32 -> 0 | CM32: =IF($N$32="","",$N$32) | CR32: =CP32+CQ32 -> 0 | CT32: =IF($N$32="","",$N$32) | CY32: =CW32+CX32 -> 0 | DA32: =IF($N$32="","",$N$32) | DF32: =DD32+DE32 -> 0 | DH32: =IF($N$32="","",$N$32) | DM32: =DK32+DL32 -> 0 | DO32: =IF($N$32="","",$N$32) | DT32: =DR32+DS32 -> 0 | DV32: =IF($N$32="","",$N$32) | EA32: =DY32+DZ32 -> 0 | EC32: =IF($N$32="","",$N$32) | EH32: =EF32+EG32 -> 0 | EJ32: =IF($N$32="","",$N$32) | EO32: =EM32+EN32 -> 0 | EQ32: =IF($N$32="","",$N$32) | EV32: =ET32+EU32 -> 0
